Created Output Log File: /workdir/tasks_run/data/logs/calculator_script_20240910_15h09m17s.txtStarting Block1 ... 
========================================
Starting Block1, Trial 1... 
========================================
Mean ROI Activation: 415.5724792480469
Ending Block1, Trial 1... 
========================================
Starting Block1, Trial 2... 
========================================
Mean ROI Activation: 414.5749816894531
Ending Block1, Trial 2... 
========================================
Starting Block1, Trial 3... 
========================================
Error:

Traceback (most recent call last):
  File "/workdir/tasks_run/scripts/nf_calc.py", line 27, in wrapper
    updated_dictionary = func(*args, **kwargs)
  File "/workdir/tasks_run/scripts/nf_calc.py", line 81, in run_trial
    raise Exception
Exception

Retries left: 2
Error:

Traceback (most recent call last):
  File "/workdir/tasks_run/scripts/nf_calc.py", line 27, in wrapper
    updated_dictionary = func(*args, **kwargs)
  File "/workdir/tasks_run/scripts/nf_calc.py", line 81, in run_trial
    raise Exception
Exception

Retries left: 1
Error:

Traceback (most recent call last):
  File "/workdir/tasks_run/scripts/nf_calc.py", line 27, in wrapper
    updated_dictionary = func(*args, **kwargs)
  File "/workdir/tasks_run/scripts/nf_calc.py", line 81, in run_trial
    raise Exception
Exception

Retries left: 0
Ran out of retries. Skipping this trial.
Ending Block1, Trial 3... 
========================================
Starting Block1, Trial 4... 
========================================
Mean ROI Activation: 415.2086181640625
Ending Block1, Trial 4... 
========================================
Starting Block1, Trial 5... 
========================================
Mean ROI Activation: 415.9109802246094
Ending Block1, Trial 5... 
========================================
Starting Block1, Trial 6... 
========================================
Error:

Traceback (most recent call last):
  File "/workdir/tasks_run/scripts/nf_calc.py", line 27, in wrapper
    updated_dictionary = func(*args, **kwargs)
  File "/workdir/tasks_run/scripts/nf_calc.py", line 81, in run_trial
    raise Exception
Exception

Retries left: 2
Error:

Traceback (most recent call last):
  File "/workdir/tasks_run/scripts/nf_calc.py", line 27, in wrapper
    updated_dictionary = func(*args, **kwargs)
  File "/workdir/tasks_run/scripts/nf_calc.py", line 81, in run_trial
    raise Exception
Exception

Retries left: 1
Error:

Traceback (most recent call last):
  File "/workdir/tasks_run/scripts/nf_calc.py", line 27, in wrapper
    updated_dictionary = func(*args, **kwargs)
  File "/workdir/tasks_run/scripts/nf_calc.py", line 81, in run_trial
    raise Exception
Exception

Retries left: 0
Ran out of retries. Skipping this trial.
Ending Block1, Trial 6... 
========================================
Starting Block1, Trial 7... 
========================================
Mean ROI Activation: 413.8758850097656
Ending Block1, Trial 7... 
========================================
Starting Block1, Trial 8... 
========================================
Error:
Cannot Find Nifti Image After dcm2niix
Traceback (most recent call last):
  File "/workdir/tasks_run/scripts/nf_calc.py", line 27, in wrapper
    updated_dictionary = func(*args, **kwargs)
  File "/workdir/tasks_run/scripts/nf_calc.py", line 78, in run_trial
    dictionary[f"block{block}"][f"trial{trial}"]["nifti_path"] = file_handler.dicom_to_nifti(dicom_file=dicom_path, trial=trial)
  File "/workdir/tasks_run/scripts/file_handler.py", line 70, in dicom_to_nifti
    raise Exception("Cannot Find Nifti Image After dcm2niix")
Exception: Cannot Find Nifti Image After dcm2niix

Retries left: 2
Error:
Cannot Find Nifti Image After dcm2niix
Traceback (most recent call last):
  File "/workdir/tasks_run/scripts/nf_calc.py", line 27, in wrapper
    updated_dictionary = func(*args, **kwargs)
  File "/workdir/tasks_run/scripts/nf_calc.py", line 78, in run_trial
    dictionary[f"block{block}"][f"trial{trial}"]["nifti_path"] = file_handler.dicom_to_nifti(dicom_file=dicom_path, trial=trial)
  File "/workdir/tasks_run/scripts/file_handler.py", line 70, in dicom_to_nifti
    raise Exception("Cannot Find Nifti Image After dcm2niix")
Exception: Cannot Find Nifti Image After dcm2niix

Retries left: 1
Error:
Cannot Find Nifti Image After dcm2niix
Traceback (most recent call last):
  File "/workdir/tasks_run/scripts/nf_calc.py", line 27, in wrapper
    updated_dictionary = func(*args, **kwargs)
  File "/workdir/tasks_run/scripts/nf_calc.py", line 78, in run_trial
    dictionary[f"block{block}"][f"trial{trial}"]["nifti_path"] = file_handler.dicom_to_nifti(dicom_file=dicom_path, trial=trial)
  File "/workdir/tasks_run/scripts/file_handler.py", line 70, in dicom_to_nifti
    raise Exception("Cannot Find Nifti Image After dcm2niix")
Exception: Cannot Find Nifti Image After dcm2niix

Retries left: 0
Ran out of retries. Skipping this trial.
Ending Block1, Trial 8... 
Ending Block Due to Too Many Issues
Nifti Outdir Cleared
Starting Block2 ... 
========================================
Starting Block2, Trial 1... 
========================================
Mean ROI Activation: 415.1933288574219
Ending Block2, Trial 1... 
========================================
Starting Block2, Trial 2... 
========================================
Mean ROI Activation: 413.9335632324219
Ending Block2, Trial 2... 
========================================
Starting Block2, Trial 3... 
========================================
Error:

Traceback (most recent call last):
  File "/workdir/tasks_run/scripts/nf_calc.py", line 27, in wrapper
    updated_dictionary = func(*args, **kwargs)
  File "/workdir/tasks_run/scripts/nf_calc.py", line 81, in run_trial
    raise Exception
Exception

Retries left: 2
Error:

Traceback (most recent call last):
  File "/workdir/tasks_run/scripts/nf_calc.py", line 27, in wrapper
    updated_dictionary = func(*args, **kwargs)
  File "/workdir/tasks_run/scripts/nf_calc.py", line 81, in run_trial
    raise Exception
Exception

Retries left: 1
Error:

Traceback (most recent call last):
  File "/workdir/tasks_run/scripts/nf_calc.py", line 27, in wrapper
    updated_dictionary = func(*args, **kwargs)
  File "/workdir/tasks_run/scripts/nf_calc.py", line 81, in run_trial
    raise Exception
Exception

Retries left: 0
Ran out of retries. Skipping this trial.
Ending Block2, Trial 3... 
========================================
Starting Block2, Trial 4... 
========================================
Mean ROI Activation: 414.67352294921875
Ending Block2, Trial 4... 
========================================
Starting Block2, Trial 5... 
========================================
---- Keyboard Interrupt Detected ----
What Would You Like to Do?
(1) Continue With The Block
(2) End The Session
(3) Start New Block
Ok, Let's End the Session...
Nifti Outdir Cleared
Ending Session Due to: keyboard interrupt
Session Data:
Running Main Calculation Script ... 
