Created Output Log File: /workdir/tasks_run/data/logs/calculator_script_20240909_17h00m00s.txtStarting Block1 ... 
========================================
Starting Block1, Trial 1... 
========================================
Ending Block1, Trial 1... 
========================================
Starting Block1, Trial 2... 
========================================
Ending Block1, Trial 2... 
========================================
Starting Block1, Trial 3... 
========================================
Error:

Traceback (most recent call last):
  File "/workdir/tasks_run/scripts/main.py", line 24, in wrapper
    updated_dictionary = func(*args, **kwargs)
  File "/workdir/tasks_run/scripts/main.py", line 80, in run_trial
    raise Exception
Exception

Retries left: 2
Error:

Traceback (most recent call last):
  File "/workdir/tasks_run/scripts/main.py", line 24, in wrapper
    updated_dictionary = func(*args, **kwargs)
  File "/workdir/tasks_run/scripts/main.py", line 80, in run_trial
    raise Exception
Exception

Retries left: 1
Error:

Traceback (most recent call last):
  File "/workdir/tasks_run/scripts/main.py", line 24, in wrapper
    updated_dictionary = func(*args, **kwargs)
  File "/workdir/tasks_run/scripts/main.py", line 80, in run_trial
    raise Exception
Exception

Retries left: 0
Ran out of retries. Skipping this trial.
Ending Block1, Trial 3... 
========================================
Starting Block1, Trial 4... 
========================================
Ending Block1, Trial 4... 
========================================
Starting Block1, Trial 5... 
========================================
Ending Block1, Trial 5... 
========================================
Starting Block1, Trial 6... 
========================================
Error:

Traceback (most recent call last):
  File "/workdir/tasks_run/scripts/main.py", line 24, in wrapper
    updated_dictionary = func(*args, **kwargs)
  File "/workdir/tasks_run/scripts/main.py", line 80, in run_trial
    raise Exception
Exception

Retries left: 2
Error:

Traceback (most recent call last):
  File "/workdir/tasks_run/scripts/main.py", line 24, in wrapper
    updated_dictionary = func(*args, **kwargs)
  File "/workdir/tasks_run/scripts/main.py", line 80, in run_trial
    raise Exception
Exception

Retries left: 1
Error:

Traceback (most recent call last):
  File "/workdir/tasks_run/scripts/main.py", line 24, in wrapper
    updated_dictionary = func(*args, **kwargs)
  File "/workdir/tasks_run/scripts/main.py", line 80, in run_trial
    raise Exception
Exception

Retries left: 0
Ran out of retries. Skipping this trial.
Ending Block1, Trial 6... 
========================================
Starting Block1, Trial 7... 
========================================
Ending Block1, Trial 7... 
========================================
Starting Block1, Trial 8... 
========================================
Ending Block1, Trial 8... 
========================================
Starting Block1, Trial 9... 
========================================
Error:

Traceback (most recent call last):
  File "/workdir/tasks_run/scripts/main.py", line 24, in wrapper
    updated_dictionary = func(*args, **kwargs)
  File "/workdir/tasks_run/scripts/main.py", line 80, in run_trial
    raise Exception
Exception

Retries left: 2
---- Keyboard Interrupt Detected ----
What Would You Like to Do?
(1) Continue With The Block
(2) End The Session
(3) Start New Block
Ok, Let's End the Session...
Session Data:
